Unhandled exception in thread started by <function wrapper at 0x7f603921e2a8>
Performing system checks...

Traceback (most recent call last):
  File "/root/python27/lib/python2.7/site-packages/django/utils/autoreload.py", line 226, in wrapper
    fn(*args, **kwargs)
  File "/root/python27/lib/python2.7/site-packages/django/core/management/commands/runserver.py", line 121, in inner_run
    self.check(display_num_errors=True)
  File "/root/python27/lib/python2.7/site-packages/django/core/management/base.py", line 374, in check
    include_deployment_checks=include_deployment_checks,
  File "/root/python27/lib/python2.7/site-packages/django/core/management/base.py", line 361, in _run_checks
    return checks.run_checks(**kwargs)
  File "/root/python27/lib/python2.7/site-packages/django/core/checks/registry.py", line 81, in run_checks
    new_errors = check(app_configs=app_configs)
  File "/root/python27/lib/python2.7/site-packages/django/core/checks/urls.py", line 14, in check_url_config
    return check_resolver(resolver)
  File "/root/python27/lib/python2.7/site-packages/django/core/checks/urls.py", line 24, in check_resolver
    for pattern in resolver.url_patterns:
  File "/root/python27/lib/python2.7/site-packages/django/utils/functional.py", line 35, in __get__
    res = instance.__dict__[self.name] = self.func(instance)
  File "/root/python27/lib/python2.7/site-packages/django/urls/resolvers.py", line 313, in url_patterns
    patterns = getattr(self.urlconf_module, "urlpatterns", self.urlconf_module)
  File "/root/python27/lib/python2.7/site-packages/django/utils/functional.py", line 35, in __get__
    res = instance.__dict__[self.name] = self.func(instance)
  File "/root/python27/lib/python2.7/site-packages/django/urls/resolvers.py", line 306, in urlconf_module
    return import_module(self.urlconf_name)
  File "/root/python27/lib/python2.7/importlib/__init__.py", line 37, in import_module
    __import__(name)
  File "/root/scripts/restfulapi/restfulapi/urls.py", line 21, in <module>
    url(r'^', include('api.urls')),
  File "/root/python27/lib/python2.7/site-packages/django/conf/urls/__init__.py", line 50, in include
    urlconf_module = import_module(urlconf_module)
  File "/root/python27/lib/python2.7/importlib/__init__.py", line 37, in import_module
    __import__(name)
  File "/root/scripts/restfulapi/api/urls.py", line 2, in <module>
    from api import views
  File "/root/scripts/restfulapi/api/views.py", line 7
SyntaxError: Non-ASCII character '\xe5' in file /root/scripts/restfulapi/api/views.py on line 7, but no encoding declared; see http://python.org/dev/peps/pep-0263/ for details
Invalid HTTP_HOST header: '192.168.199.109:8000'. You may need to add u'192.168.199.109' to ALLOWED_HOSTS.
[17/May/2017 00:11:17] "GET / HTTP/1.1" 400 61500
Invalid HTTP_HOST header: '192.168.199.109:8000'. You may need to add u'192.168.199.109' to ALLOWED_HOSTS.
[17/May/2017 00:11:18] "GET /favicon.ico HTTP/1.1" 400 61449
Performing system checks...

System check identified no issues (0 silenced).

You have 13 unapplied migration(s). Your project may not work properly until you apply the migrations for app(s): admin, auth, contenttypes, sessions.
Run 'python manage.py migrate' to apply them.
May 17, 2017 - 00:11:13
Django version 1.10.6, using settings 'restfulapi.settings'
Starting development server at http://0.0.0.0:8000/
Quit the server with CONTROL-C.
Not Found: /
[17/May/2017 00:13:16] "GET / HTTP/1.1" 404 2067
Not Found: /favicon.ico
[17/May/2017 00:13:16] "GET /favicon.ico HTTP/1.1" 404 2100
[17/May/2017 00:13:51] "GET /api HTTP/1.1" 301 0
Internal Server Error: /api/
Traceback (most recent call last):
  File "/root/python27/lib/python2.7/site-packages/django/core/handlers/exception.py", line 42, in inner
    response = get_response(request)
  File "/root/python27/lib/python2.7/site-packages/django/core/handlers/base.py", line 187, in _get_response
    response = self.process_exception_by_middleware(e, request)
  File "/root/python27/lib/python2.7/site-packages/django/core/handlers/base.py", line 185, in _get_response
    response = wrapped_callback(request, *callback_args, **callback_kwargs)
  File "/root/scripts/restfulapi/api/views.py", line 9, in api_list
    return JsonResponse("hello")
  File "/root/python27/lib/python2.7/site-packages/django/http/response.py", line 514, in __init__
    'In order to allow non-dict objects to be serialized set the '
TypeError: In order to allow non-dict objects to be serialized set the safe parameter to False.
[17/May/2017 00:13:51] "GET /api/ HTTP/1.1" 500 67622
Performing system checks...

System check identified no issues (0 silenced).

You have 13 unapplied migration(s). Your project may not work properly until you apply the migrations for app(s): admin, auth, contenttypes, sessions.
Run 'python manage.py migrate' to apply them.
May 17, 2017 - 00:13:10
Django version 1.10.6, using settings 'restfulapi.settings'
Starting development server at http://0.0.0.0:8000/
Quit the server with CONTROL-C.
Internal Server Error: /api/
Traceback (most recent call last):
  File "/root/python27/lib/python2.7/site-packages/django/core/handlers/exception.py", line 42, in inner
    response = get_response(request)
  File "/root/python27/lib/python2.7/site-packages/django/core/handlers/base.py", line 187, in _get_response
    response = self.process_exception_by_middleware(e, request)
  File "/root/python27/lib/python2.7/site-packages/django/core/handlers/base.py", line 185, in _get_response
    response = wrapped_callback(request, *callback_args, **callback_kwargs)
  File "/root/scripts/restfulapi/api/views.py", line 9, in api_list
    return JsonResponse("hello:world")
  File "/root/python27/lib/python2.7/site-packages/django/http/response.py", line 514, in __init__
    'In order to allow non-dict objects to be serialized set the '
TypeError: In order to allow non-dict objects to be serialized set the safe parameter to False.
[17/May/2017 00:30:30] "GET /api/ HTTP/1.1" 500 67775
Performing system checks...

System check identified no issues (0 silenced).

You have 13 unapplied migration(s). Your project may not work properly until you apply the migrations for app(s): admin, auth, contenttypes, sessions.
Run 'python manage.py migrate' to apply them.
May 17, 2017 - 00:30:26
Django version 1.10.6, using settings 'restfulapi.settings'
Starting development server at http://0.0.0.0:8000/
Quit the server with CONTROL-C.
Internal Server Error: /api/
Traceback (most recent call last):
  File "/root/python27/lib/python2.7/site-packages/django/core/handlers/exception.py", line 42, in inner
    response = get_response(request)
  File "/root/python27/lib/python2.7/site-packages/django/core/handlers/base.py", line 187, in _get_response
    response = self.process_exception_by_middleware(e, request)
  File "/root/python27/lib/python2.7/site-packages/django/core/handlers/base.py", line 185, in _get_response
    response = wrapped_callback(request, *callback_args, **callback_kwargs)
  File "/root/scripts/restfulapi/api/views.py", line 9, in api_list
    return JsonResponse("{'Alice': '2341', 'Beth': '9102', 'Cecil': '3258'}")
  File "/root/python27/lib/python2.7/site-packages/django/http/response.py", line 514, in __init__
    'In order to allow non-dict objects to be serialized set the '
TypeError: In order to allow non-dict objects to be serialized set the safe parameter to False.
[17/May/2017 00:31:28] "GET /api/ HTTP/1.1" 500 68038
Internal Server Error: /api/
Traceback (most recent call last):
  File "/root/python27/lib/python2.7/site-packages/django/core/handlers/exception.py", line 42, in inner
    response = get_response(request)
  File "/root/python27/lib/python2.7/site-packages/django/core/handlers/base.py", line 187, in _get_response
    response = self.process_exception_by_middleware(e, request)
  File "/root/python27/lib/python2.7/site-packages/django/core/handlers/base.py", line 185, in _get_response
    response = wrapped_callback(request, *callback_args, **callback_kwargs)
  File "/root/scripts/restfulapi/api/views.py", line 9, in api_list
    return JsonResponse("{'Alice': '2341', 'Beth': '9102', 'Cecil': '3258'}")
  File "/root/python27/lib/python2.7/site-packages/django/http/response.py", line 514, in __init__
    'In order to allow non-dict objects to be serialized set the '
TypeError: In order to allow non-dict objects to be serialized set the safe parameter to False.
[17/May/2017 00:31:33] "GET /api/ HTTP/1.1" 500 68038
Internal Server Error: /api/
Traceback (most recent call last):
  File "/root/python27/lib/python2.7/site-packages/django/core/handlers/exception.py", line 42, in inner
    response = get_response(request)
  File "/root/python27/lib/python2.7/site-packages/django/core/handlers/base.py", line 187, in _get_response
    response = self.process_exception_by_middleware(e, request)
  File "/root/python27/lib/python2.7/site-packages/django/core/handlers/base.py", line 185, in _get_response
    response = wrapped_callback(request, *callback_args, **callback_kwargs)
  File "/root/scripts/restfulapi/api/views.py", line 9, in api_list
    return JsonResponse("{'Alice': '2341', 'Beth': '9102', 'Cecil': '3258'}")
  File "/root/python27/lib/python2.7/site-packages/django/http/response.py", line 514, in __init__
    'In order to allow non-dict objects to be serialized set the '
TypeError: In order to allow non-dict objects to be serialized set the safe parameter to False.
[17/May/2017 00:31:44] "GET /api/ HTTP/1.1" 500 68038
Internal Server Error: /api/
Traceback (most recent call last):
  File "/root/python27/lib/python2.7/site-packages/django/core/handlers/exception.py", line 42, in inner
    response = get_response(request)
  File "/root/python27/lib/python2.7/site-packages/django/core/handlers/base.py", line 187, in _get_response
    response = self.process_exception_by_middleware(e, request)
  File "/root/python27/lib/python2.7/site-packages/django/core/handlers/base.py", line 185, in _get_response
    response = wrapped_callback(request, *callback_args, **callback_kwargs)
  File "/root/scripts/restfulapi/api/views.py", line 9, in api_list
    return JsonResponse("{'Alice': '2341', 'Beth': '9102', 'Cecil': '3258'}")
  File "/root/python27/lib/python2.7/site-packages/django/http/response.py", line 514, in __init__
    'In order to allow non-dict objects to be serialized set the '
TypeError: In order to allow non-dict objects to be serialized set the safe parameter to False.
[17/May/2017 00:31:47] "GET /api/ HTTP/1.1" 500 68038
Performing system checks...

System check identified no issues (0 silenced).

You have 13 unapplied migration(s). Your project may not work properly until you apply the migrations for app(s): admin, auth, contenttypes, sessions.
Run 'python manage.py migrate' to apply them.
May 17, 2017 - 00:31:23
Django version 1.10.6, using settings 'restfulapi.settings'
Starting development server at http://0.0.0.0:8000/
Quit the server with CONTROL-C.
Unhandled exception in thread started by <function wrapper at 0x7f5ec32792a8>
Performing system checks...

Traceback (most recent call last):
  File "/root/python27/lib/python2.7/site-packages/django/utils/autoreload.py", line 226, in wrapper
    fn(*args, **kwargs)
  File "/root/python27/lib/python2.7/site-packages/django/core/management/commands/runserver.py", line 121, in inner_run
    self.check(display_num_errors=True)
  File "/root/python27/lib/python2.7/site-packages/django/core/management/base.py", line 374, in check
    include_deployment_checks=include_deployment_checks,
  File "/root/python27/lib/python2.7/site-packages/django/core/management/base.py", line 361, in _run_checks
    return checks.run_checks(**kwargs)
  File "/root/python27/lib/python2.7/site-packages/django/core/checks/registry.py", line 81, in run_checks
    new_errors = check(app_configs=app_configs)
  File "/root/python27/lib/python2.7/site-packages/django/core/checks/urls.py", line 14, in check_url_config
    return check_resolver(resolver)
  File "/root/python27/lib/python2.7/site-packages/django/core/checks/urls.py", line 24, in check_resolver
    for pattern in resolver.url_patterns:
  File "/root/python27/lib/python2.7/site-packages/django/utils/functional.py", line 35, in __get__
    res = instance.__dict__[self.name] = self.func(instance)
  File "/root/python27/lib/python2.7/site-packages/django/urls/resolvers.py", line 313, in url_patterns
    patterns = getattr(self.urlconf_module, "urlpatterns", self.urlconf_module)
  File "/root/python27/lib/python2.7/site-packages/django/utils/functional.py", line 35, in __get__
    res = instance.__dict__[self.name] = self.func(instance)
  File "/root/python27/lib/python2.7/site-packages/django/urls/resolvers.py", line 306, in urlconf_module
    return import_module(self.urlconf_name)
  File "/root/python27/lib/python2.7/importlib/__init__.py", line 37, in import_module
    __import__(name)
  File "/root/scripts/restfulapi/restfulapi/urls.py", line 21, in <module>
    url(r'^', include('api.urls')),
  File "/root/python27/lib/python2.7/site-packages/django/conf/urls/__init__.py", line 50, in include
    urlconf_module = import_module(urlconf_module)
  File "/root/python27/lib/python2.7/importlib/__init__.py", line 37, in import_module
    __import__(name)
  File "/root/scripts/restfulapi/api/urls.py", line 2, in <module>
    from api import views
  File "/root/scripts/restfulapi/api/views.py", line 9
    return JsonResponse({"'Alice': '2341', 'Beth': '9102', 'Cecil': '3258'}",safe=False)
                                                                                 ^
SyntaxError: invalid syntax
Performing system checks...

System check identified no issues (0 silenced).

You have 13 unapplied migration(s). Your project may not work properly until you apply the migrations for app(s): admin, auth, contenttypes, sessions.
Run 'python manage.py migrate' to apply them.
May 17, 2017 - 00:34:46
Django version 1.10.6, using settings 'restfulapi.settings'
Starting development server at http://0.0.0.0:8000/
Quit the server with CONTROL-C.
[17/May/2017 00:34:57] "GET /api/ HTTP/1.1" 200 52
[17/May/2017 19:48:39] "GET /api/ HTTP/1.1" 200 52
[17/May/2017 19:48:41] "GET /api/ HTTP/1.1" 200 52
[17/May/2017 19:54:15] "GET /api/ HTTP/1.1" 200 52
Performing system checks...

System check identified no issues (0 silenced).

You have 13 unapplied migration(s). Your project may not work properly until you apply the migrations for app(s): admin, auth, contenttypes, sessions.
Run 'python manage.py migrate' to apply them.
May 17, 2017 - 19:48:19
Django version 1.10.6, using settings 'restfulapi.settings'
Starting development server at http://0.0.0.0:8000/
Quit the server with CONTROL-C.
[17/May/2017 19:54:40] "GET /api/ HTTP/1.1" 200 50
[17/May/2017 19:54:42] "GET /api/ HTTP/1.1" 200 50
[17/May/2017 19:54:44] "GET /api/ HTTP/1.1" 200 50
Performing system checks...

System check identified no issues (0 silenced).

You have 13 unapplied migration(s). Your project may not work properly until you apply the migrations for app(s): admin, auth, contenttypes, sessions.
Run 'python manage.py migrate' to apply them.
May 17, 2017 - 19:54:37
Django version 1.10.6, using settings 'restfulapi.settings'
Starting development server at http://0.0.0.0:8000/
Quit the server with CONTROL-C.
[17/May/2017 19:57:41] "GET /admin HTTP/1.1" 301 0
[17/May/2017 19:57:41] "GET /admin/ HTTP/1.1" 302 0
[17/May/2017 19:57:41] "GET /admin/login/?next=/admin/ HTTP/1.1" 200 1657
[17/May/2017 19:57:41] "GET /static/admin/css/login.css HTTP/1.1" 200 1203
[17/May/2017 19:57:41] "GET /static/admin/css/base.css HTTP/1.1" 200 15937
[17/May/2017 19:57:41] "GET /static/admin/css/fonts.css HTTP/1.1" 200 423
[17/May/2017 19:57:41] "GET /static/admin/fonts/Roboto-Regular-webfont.woff HTTP/1.1" 200 80304
[17/May/2017 19:57:41] "GET /static/admin/fonts/Roboto-Light-webfont.woff HTTP/1.1" 200 81348
Internal Server Error: /admin/login/
Traceback (most recent call last):
  File "/root/python27/lib/python2.7/site-packages/django/core/handlers/exception.py", line 42, in inner
    response = get_response(request)
  File "/root/python27/lib/python2.7/site-packages/django/core/handlers/base.py", line 187, in _get_response
    response = self.process_exception_by_middleware(e, request)
  File "/root/python27/lib/python2.7/site-packages/django/core/handlers/base.py", line 185, in _get_response
    response = wrapped_callback(request, *callback_args, **callback_kwargs)
  File "/root/python27/lib/python2.7/site-packages/django/views/decorators/cache.py", line 57, in _wrapped_view_func
    response = view_func(request, *args, **kwargs)
  File "/root/python27/lib/python2.7/site-packages/django/contrib/admin/sites.py", line 377, in login
    return login(request, **defaults)
  File "/root/python27/lib/python2.7/site-packages/django/contrib/auth/views.py", line 47, in inner
    return func(*args, **kwargs)
  File "/root/python27/lib/python2.7/site-packages/django/views/decorators/debug.py", line 76, in sensitive_post_parameters_wrapper
    return view(request, *args, **kwargs)
  File "/root/python27/lib/python2.7/site-packages/django/utils/decorators.py", line 149, in _wrapped_view
    response = view_func(request, *args, **kwargs)
  File "/root/python27/lib/python2.7/site-packages/django/views/decorators/cache.py", line 57, in _wrapped_view_func
    response = view_func(request, *args, **kwargs)
  File "/root/python27/lib/python2.7/site-packages/django/contrib/auth/views.py", line 81, in login
    if form.is_valid():
  File "/root/python27/lib/python2.7/site-packages/django/forms/forms.py", line 169, in is_valid
    return self.is_bound and not self.errors
  File "/root/python27/lib/python2.7/site-packages/django/forms/forms.py", line 161, in errors
    self.full_clean()
  File "/root/python27/lib/python2.7/site-packages/django/forms/forms.py", line 371, in full_clean
    self._clean_form()
  File "/root/python27/lib/python2.7/site-packages/django/forms/forms.py", line 398, in _clean_form
    cleaned_data = self.clean()
  File "/root/python27/lib/python2.7/site-packages/django/contrib/auth/forms.py", line 191, in clean
    self.user_cache = authenticate(username=username, password=password)
  File "/root/python27/lib/python2.7/site-packages/django/contrib/auth/__init__.py", line 74, in authenticate
    user = backend.authenticate(**credentials)
  File "/root/python27/lib/python2.7/site-packages/django/contrib/auth/backends.py", line 17, in authenticate
    user = UserModel._default_manager.get_by_natural_key(username)
  File "/root/python27/lib/python2.7/site-packages/django/contrib/auth/base_user.py", line 48, in get_by_natural_key
    return self.get(**{self.model.USERNAME_FIELD: username})
  File "/root/python27/lib/python2.7/site-packages/django/db/models/manager.py", line 85, in manager_method
    return getattr(self.get_queryset(), name)(*args, **kwargs)
  File "/root/python27/lib/python2.7/site-packages/django/db/models/query.py", line 379, in get
    num = len(clone)
  File "/root/python27/lib/python2.7/site-packages/django/db/models/query.py", line 238, in __len__
    self._fetch_all()
  File "/root/python27/lib/python2.7/site-packages/django/db/models/query.py", line 1087, in _fetch_all
    self._result_cache = list(self.iterator())
  File "/root/python27/lib/python2.7/site-packages/django/db/models/query.py", line 54, in __iter__
    results = compiler.execute_sql()
  File "/root/python27/lib/python2.7/site-packages/django/db/models/sql/compiler.py", line 835, in execute_sql
    cursor.execute(sql, params)
  File "/root/python27/lib/python2.7/site-packages/django/db/backends/utils.py", line 79, in execute
    return super(CursorDebugWrapper, self).execute(sql, params)
  File "/root/python27/lib/python2.7/site-packages/django/db/backends/utils.py", line 64, in execute
    return self.cursor.execute(sql, params)
  File "/root/python27/lib/python2.7/site-packages/django/db/utils.py", line 94, in __exit__
    six.reraise(dj_exc_type, dj_exc_value, traceback)
  File "/root/python27/lib/python2.7/site-packages/django/db/backends/utils.py", line 64, in execute
    return self.cursor.execute(sql, params)
  File "/root/python27/lib/python2.7/site-packages/django/db/backends/sqlite3/base.py", line 337, in execute
    return Database.Cursor.execute(self, query, params)
OperationalError: no such table: auth_user
[17/May/2017 19:57:46] "POST /admin/login/?next=/admin/ HTTP/1.1" 500 178290
[17/May/2017 19:57:48] "GET /admin/login/?next=/admin/ HTTP/1.1" 200 1657
Internal Server Error: /admin/login/
Traceback (most recent call last):
  File "/root/python27/lib/python2.7/site-packages/django/core/handlers/exception.py", line 42, in inner
    response = get_response(request)
  File "/root/python27/lib/python2.7/site-packages/django/core/handlers/base.py", line 187, in _get_response
    response = self.process_exception_by_middleware(e, request)
  File "/root/python27/lib/python2.7/site-packages/django/core/handlers/base.py", line 185, in _get_response
    response = wrapped_callback(request, *callback_args, **callback_kwargs)
  File "/root/python27/lib/python2.7/site-packages/django/views/decorators/cache.py", line 57, in _wrapped_view_func
    response = view_func(request, *args, **kwargs)
  File "/root/python27/lib/python2.7/site-packages/django/contrib/admin/sites.py", line 377, in login
    return login(request, **defaults)
  File "/root/python27/lib/python2.7/site-packages/django/contrib/auth/views.py", line 47, in inner
    return func(*args, **kwargs)
  File "/root/python27/lib/python2.7/site-packages/django/views/decorators/debug.py", line 76, in sensitive_post_parameters_wrapper
    return view(request, *args, **kwargs)
  File "/root/python27/lib/python2.7/site-packages/django/utils/decorators.py", line 149, in _wrapped_view
    response = view_func(request, *args, **kwargs)
  File "/root/python27/lib/python2.7/site-packages/django/views/decorators/cache.py", line 57, in _wrapped_view_func
    response = view_func(request, *args, **kwargs)
  File "/root/python27/lib/python2.7/site-packages/django/contrib/auth/views.py", line 81, in login
    if form.is_valid():
  File "/root/python27/lib/python2.7/site-packages/django/forms/forms.py", line 169, in is_valid
    return self.is_bound and not self.errors
  File "/root/python27/lib/python2.7/site-packages/django/forms/forms.py", line 161, in errors
    self.full_clean()
  File "/root/python27/lib/python2.7/site-packages/django/forms/forms.py", line 371, in full_clean
    self._clean_form()
  File "/root/python27/lib/python2.7/site-packages/django/forms/forms.py", line 398, in _clean_form
    cleaned_data = self.clean()
  File "/root/python27/lib/python2.7/site-packages/django/contrib/auth/forms.py", line 191, in clean
    self.user_cache = authenticate(username=username, password=password)
  File "/root/python27/lib/python2.7/site-packages/django/contrib/auth/__init__.py", line 74, in authenticate
    user = backend.authenticate(**credentials)
  File "/root/python27/lib/python2.7/site-packages/django/contrib/auth/backends.py", line 17, in authenticate
    user = UserModel._default_manager.get_by_natural_key(username)
  File "/root/python27/lib/python2.7/site-packages/django/contrib/auth/base_user.py", line 48, in get_by_natural_key
    return self.get(**{self.model.USERNAME_FIELD: username})
  File "/root/python27/lib/python2.7/site-packages/django/db/models/manager.py", line 85, in manager_method
    return getattr(self.get_queryset(), name)(*args, **kwargs)
  File "/root/python27/lib/python2.7/site-packages/django/db/models/query.py", line 379, in get
    num = len(clone)
  File "/root/python27/lib/python2.7/site-packages/django/db/models/query.py", line 238, in __len__
    self._fetch_all()
  File "/root/python27/lib/python2.7/site-packages/django/db/models/query.py", line 1087, in _fetch_all
    self._result_cache = list(self.iterator())
  File "/root/python27/lib/python2.7/site-packages/django/db/models/query.py", line 54, in __iter__
    results = compiler.execute_sql()
  File "/root/python27/lib/python2.7/site-packages/django/db/models/sql/compiler.py", line 835, in execute_sql
    cursor.execute(sql, params)
  File "/root/python27/lib/python2.7/site-packages/django/db/backends/utils.py", line 79, in execute
    return super(CursorDebugWrapper, self).execute(sql, params)
  File "/root/python27/lib/python2.7/site-packages/django/db/backends/utils.py", line 64, in execute
    return self.cursor.execute(sql, params)
  File "/root/python27/lib/python2.7/site-packages/django/db/utils.py", line 94, in __exit__
    six.reraise(dj_exc_type, dj_exc_value, traceback)
  File "/root/python27/lib/python2.7/site-packages/django/db/backends/utils.py", line 64, in execute
    return self.cursor.execute(sql, params)
  File "/root/python27/lib/python2.7/site-packages/django/db/backends/sqlite3/base.py", line 337, in execute
    return Database.Cursor.execute(self, query, params)
OperationalError: no such table: auth_user
[17/May/2017 19:59:49] "POST /admin/login/?next=/admin/ HTTP/1.1" 500 178294
Performing system checks...

System check identified no issues (0 silenced).

You have 13 unapplied migration(s). Your project may not work properly until you apply the migrations for app(s): admin, auth, contenttypes, sessions.
Run 'python manage.py migrate' to apply them.
May 17, 2017 - 19:55:03
Django version 1.10.6, using settings 'restfulapi.settings'
Starting development server at http://0.0.0.0:8000/
Quit the server with CONTROL-C.
[17/May/2017 21:18:03] "GET /admin/ HTTP/1.1" 302 0
[17/May/2017 21:18:03] "GET /admin/login/?next=/admin/ HTTP/1.1" 200 1657
Internal Server Error: /admin/login/
Traceback (most recent call last):
  File "/root/python27/lib/python2.7/site-packages/django/core/handlers/exception.py", line 42, in inner
    response = get_response(request)
  File "/root/python27/lib/python2.7/site-packages/django/core/handlers/base.py", line 187, in _get_response
    response = self.process_exception_by_middleware(e, request)
  File "/root/python27/lib/python2.7/site-packages/django/core/handlers/base.py", line 185, in _get_response
    response = wrapped_callback(request, *callback_args, **callback_kwargs)
  File "/root/python27/lib/python2.7/site-packages/django/views/decorators/cache.py", line 57, in _wrapped_view_func
    response = view_func(request, *args, **kwargs)
  File "/root/python27/lib/python2.7/site-packages/django/contrib/admin/sites.py", line 377, in login
    return login(request, **defaults)
  File "/root/python27/lib/python2.7/site-packages/django/contrib/auth/views.py", line 47, in inner
    return func(*args, **kwargs)
  File "/root/python27/lib/python2.7/site-packages/django/views/decorators/debug.py", line 76, in sensitive_post_parameters_wrapper
    return view(request, *args, **kwargs)
  File "/root/python27/lib/python2.7/site-packages/django/utils/decorators.py", line 149, in _wrapped_view
    response = view_func(request, *args, **kwargs)
  File "/root/python27/lib/python2.7/site-packages/django/views/decorators/cache.py", line 57, in _wrapped_view_func
    response = view_func(request, *args, **kwargs)
  File "/root/python27/lib/python2.7/site-packages/django/contrib/auth/views.py", line 81, in login
    if form.is_valid():
  File "/root/python27/lib/python2.7/site-packages/django/forms/forms.py", line 169, in is_valid
    return self.is_bound and not self.errors
  File "/root/python27/lib/python2.7/site-packages/django/forms/forms.py", line 161, in errors
    self.full_clean()
  File "/root/python27/lib/python2.7/site-packages/django/forms/forms.py", line 371, in full_clean
    self._clean_form()
  File "/root/python27/lib/python2.7/site-packages/django/forms/forms.py", line 398, in _clean_form
    cleaned_data = self.clean()
  File "/root/python27/lib/python2.7/site-packages/django/contrib/auth/forms.py", line 191, in clean
    self.user_cache = authenticate(username=username, password=password)
  File "/root/python27/lib/python2.7/site-packages/django/contrib/auth/__init__.py", line 74, in authenticate
    user = backend.authenticate(**credentials)
  File "/root/python27/lib/python2.7/site-packages/django/contrib/auth/backends.py", line 17, in authenticate
    user = UserModel._default_manager.get_by_natural_key(username)
  File "/root/python27/lib/python2.7/site-packages/django/contrib/auth/base_user.py", line 48, in get_by_natural_key
    return self.get(**{self.model.USERNAME_FIELD: username})
  File "/root/python27/lib/python2.7/site-packages/django/db/models/manager.py", line 85, in manager_method
    return getattr(self.get_queryset(), name)(*args, **kwargs)
  File "/root/python27/lib/python2.7/site-packages/django/db/models/query.py", line 379, in get
    num = len(clone)
  File "/root/python27/lib/python2.7/site-packages/django/db/models/query.py", line 238, in __len__
    self._fetch_all()
  File "/root/python27/lib/python2.7/site-packages/django/db/models/query.py", line 1087, in _fetch_all
    self._result_cache = list(self.iterator())
  File "/root/python27/lib/python2.7/site-packages/django/db/models/query.py", line 54, in __iter__
    results = compiler.execute_sql()
  File "/root/python27/lib/python2.7/site-packages/django/db/models/sql/compiler.py", line 835, in execute_sql
    cursor.execute(sql, params)
  File "/root/python27/lib/python2.7/site-packages/django/db/backends/utils.py", line 79, in execute
    return super(CursorDebugWrapper, self).execute(sql, params)
  File "/root/python27/lib/python2.7/site-packages/django/db/backends/utils.py", line 64, in execute
    return self.cursor.execute(sql, params)
  File "/root/python27/lib/python2.7/site-packages/django/db/utils.py", line 94, in __exit__
    six.reraise(dj_exc_type, dj_exc_value, traceback)
  File "/root/python27/lib/python2.7/site-packages/django/db/backends/utils.py", line 64, in execute
    return self.cursor.execute(sql, params)
  File "/root/python27/lib/python2.7/site-packages/django/db/backends/sqlite3/base.py", line 337, in execute
    return Database.Cursor.execute(self, query, params)
OperationalError: no such table: auth_user
[17/May/2017 21:18:06] "POST /admin/login/?next=/admin/ HTTP/1.1" 500 178325
[17/May/2017 21:18:09] "GET /admin/login/?next=/admin/ HTTP/1.1" 200 1657
Not Found: /
[17/May/2017 21:31:32] "GET / HTTP/1.1" 404 2067
[17/May/2017 21:31:35] "GET /api/ HTTP/1.1" 200 50
Performing system checks...

System check identified no issues (0 silenced).
May 17, 2017 - 21:30:53
Django version 1.10.6, using settings 'restfulapi.settings'
Starting development server at http://0.0.0.0:8000/
Quit the server with CONTROL-C.
Unhandled exception in thread started by <function wrapper at 0x7f787ec1d2a8>
Performing system checks...

Traceback (most recent call last):
  File "/root/python27/lib/python2.7/site-packages/django/utils/autoreload.py", line 226, in wrapper
    fn(*args, **kwargs)
  File "/root/python27/lib/python2.7/site-packages/django/core/management/commands/runserver.py", line 121, in inner_run
    self.check(display_num_errors=True)
  File "/root/python27/lib/python2.7/site-packages/django/core/management/base.py", line 374, in check
    include_deployment_checks=include_deployment_checks,
  File "/root/python27/lib/python2.7/site-packages/django/core/management/base.py", line 361, in _run_checks
    return checks.run_checks(**kwargs)
  File "/root/python27/lib/python2.7/site-packages/django/core/checks/registry.py", line 81, in run_checks
    new_errors = check(app_configs=app_configs)
  File "/root/python27/lib/python2.7/site-packages/django/core/checks/urls.py", line 14, in check_url_config
    return check_resolver(resolver)
  File "/root/python27/lib/python2.7/site-packages/django/core/checks/urls.py", line 24, in check_resolver
    for pattern in resolver.url_patterns:
  File "/root/python27/lib/python2.7/site-packages/django/utils/functional.py", line 35, in __get__
    res = instance.__dict__[self.name] = self.func(instance)
  File "/root/python27/lib/python2.7/site-packages/django/urls/resolvers.py", line 313, in url_patterns
    patterns = getattr(self.urlconf_module, "urlpatterns", self.urlconf_module)
  File "/root/python27/lib/python2.7/site-packages/django/utils/functional.py", line 35, in __get__
    res = instance.__dict__[self.name] = self.func(instance)
  File "/root/python27/lib/python2.7/site-packages/django/urls/resolvers.py", line 306, in urlconf_module
    return import_module(self.urlconf_name)
  File "/root/python27/lib/python2.7/importlib/__init__.py", line 37, in import_module
    __import__(name)
  File "/root/scripts/restfulapi/restfulapi/urls.py", line 21, in <module>
    url(r'^', include('api.urls')),
  File "/root/python27/lib/python2.7/site-packages/django/conf/urls/__init__.py", line 50, in include
    urlconf_module = import_module(urlconf_module)
  File "/root/python27/lib/python2.7/importlib/__init__.py", line 37, in import_module
    __import__(name)
  File "/root/scripts/restfulapi/api/urls.py", line 2, in <module>
    from api import views
  File "/root/scripts/restfulapi/api/views.py", line 8, in <module>
    @authentication_classes((SessionAuthentication, BasicAuthentication))
NameError: name 'authentication_classes' is not defined
Unhandled exception in thread started by <function wrapper at 0x7f8847b972a8>
Performing system checks...

Traceback (most recent call last):
  File "/root/python27/lib/python2.7/site-packages/django/utils/autoreload.py", line 226, in wrapper
    fn(*args, **kwargs)
  File "/root/python27/lib/python2.7/site-packages/django/core/management/commands/runserver.py", line 121, in inner_run
    self.check(display_num_errors=True)
  File "/root/python27/lib/python2.7/site-packages/django/core/management/base.py", line 374, in check
    include_deployment_checks=include_deployment_checks,
  File "/root/python27/lib/python2.7/site-packages/django/core/management/base.py", line 361, in _run_checks
    return checks.run_checks(**kwargs)
  File "/root/python27/lib/python2.7/site-packages/django/core/checks/registry.py", line 81, in run_checks
    new_errors = check(app_configs=app_configs)
  File "/root/python27/lib/python2.7/site-packages/django/core/checks/urls.py", line 14, in check_url_config
    return check_resolver(resolver)
  File "/root/python27/lib/python2.7/site-packages/django/core/checks/urls.py", line 24, in check_resolver
    for pattern in resolver.url_patterns:
  File "/root/python27/lib/python2.7/site-packages/django/utils/functional.py", line 35, in __get__
    res = instance.__dict__[self.name] = self.func(instance)
  File "/root/python27/lib/python2.7/site-packages/django/urls/resolvers.py", line 313, in url_patterns
    patterns = getattr(self.urlconf_module, "urlpatterns", self.urlconf_module)
  File "/root/python27/lib/python2.7/site-packages/django/utils/functional.py", line 35, in __get__
    res = instance.__dict__[self.name] = self.func(instance)
  File "/root/python27/lib/python2.7/site-packages/django/urls/resolvers.py", line 306, in urlconf_module
    return import_module(self.urlconf_name)
  File "/root/python27/lib/python2.7/importlib/__init__.py", line 37, in import_module
    __import__(name)
  File "/root/scripts/restfulapi/restfulapi/urls.py", line 21, in <module>
    url(r'^', include('api.urls')),
  File "/root/python27/lib/python2.7/site-packages/django/conf/urls/__init__.py", line 50, in include
    urlconf_module = import_module(urlconf_module)
  File "/root/python27/lib/python2.7/importlib/__init__.py", line 37, in import_module
    __import__(name)
  File "/root/scripts/restfulapi/api/urls.py", line 2, in <module>
    from api import views
  File "/root/scripts/restfulapi/api/views.py", line 8, in <module>
    @permission_classes((IsAuthenticated,))
NameError: name 'permission_classes' is not defined
Unhandled exception in thread started by <function wrapper at 0x7f43bc0e32a8>
Performing system checks...

Traceback (most recent call last):
  File "/root/python27/lib/python2.7/site-packages/django/utils/autoreload.py", line 226, in wrapper
    fn(*args, **kwargs)
  File "/root/python27/lib/python2.7/site-packages/django/core/management/commands/runserver.py", line 121, in inner_run
    self.check(display_num_errors=True)
  File "/root/python27/lib/python2.7/site-packages/django/core/management/base.py", line 374, in check
    include_deployment_checks=include_deployment_checks,
  File "/root/python27/lib/python2.7/site-packages/django/core/management/base.py", line 361, in _run_checks
    return checks.run_checks(**kwargs)
  File "/root/python27/lib/python2.7/site-packages/django/core/checks/registry.py", line 81, in run_checks
    new_errors = check(app_configs=app_configs)
  File "/root/python27/lib/python2.7/site-packages/django/core/checks/urls.py", line 14, in check_url_config
    return check_resolver(resolver)
  File "/root/python27/lib/python2.7/site-packages/django/core/checks/urls.py", line 24, in check_resolver
    for pattern in resolver.url_patterns:
  File "/root/python27/lib/python2.7/site-packages/django/utils/functional.py", line 35, in __get__
    res = instance.__dict__[self.name] = self.func(instance)
  File "/root/python27/lib/python2.7/site-packages/django/urls/resolvers.py", line 313, in url_patterns
    patterns = getattr(self.urlconf_module, "urlpatterns", self.urlconf_module)
  File "/root/python27/lib/python2.7/site-packages/django/utils/functional.py", line 35, in __get__
    res = instance.__dict__[self.name] = self.func(instance)
  File "/root/python27/lib/python2.7/site-packages/django/urls/resolvers.py", line 306, in urlconf_module
    return import_module(self.urlconf_name)
  File "/root/python27/lib/python2.7/importlib/__init__.py", line 37, in import_module
    __import__(name)
  File "/root/scripts/restfulapi/restfulapi/urls.py", line 21, in <module>
    url(r'^', include('api.urls')),
  File "/root/python27/lib/python2.7/site-packages/django/conf/urls/__init__.py", line 50, in include
    urlconf_module = import_module(urlconf_module)
  File "/root/python27/lib/python2.7/importlib/__init__.py", line 37, in import_module
    __import__(name)
  File "/root/scripts/restfulapi/api/urls.py", line 5, in <module>
    url(r'^api/$',views.api_list),
AttributeError: 'module' object has no attribute 'api_list'
[17/May/2017 21:48:06] "GET /api/ HTTP/1.1" 403 4542
[17/May/2017 21:48:06] "GET /static/rest_framework/css/bootstrap-tweaks.css HTTP/1.1" 200 3385
[17/May/2017 21:48:06] "GET /static/rest_framework/css/prettify.css HTTP/1.1" 200 817
[17/May/2017 21:48:06] "GET /static/rest_framework/js/ajax-form.js HTTP/1.1" 200 2876
[17/May/2017 21:48:06] "GET /static/rest_framework/css/default.css HTTP/1.1" 200 1132
[17/May/2017 21:48:06] "GET /static/rest_framework/js/csrf.js HTTP/1.1" 200 1735
[17/May/2017 21:48:06] "GET /static/rest_framework/css/bootstrap.min.css HTTP/1.1" 200 121200
[17/May/2017 21:48:06] "GET /static/rest_framework/js/jquery-1.12.4.min.js HTTP/1.1" 200 97163
[17/May/2017 21:48:06] "GET /static/rest_framework/js/bootstrap.min.js HTTP/1.1" 200 37045
[17/May/2017 21:48:07] "GET /static/rest_framework/js/prettify-min.js HTTP/1.1" 200 13632
[17/May/2017 21:48:07] "GET /static/rest_framework/js/default.js HTTP/1.1" 200 1262
[17/May/2017 21:48:07] "GET /static/rest_framework/img/grid.png HTTP/1.1" 200 1458
[17/May/2017 21:48:53] "GET /api/?format=api HTTP/1.1" 403 4575
Performing system checks...

System check identified no issues (0 silenced).
May 17, 2017 - 21:48:00
Django version 1.10.6, using settings 'restfulapi.settings'
Starting development server at http://0.0.0.0:8000/
Quit the server with CONTROL-C.
Performing system checks...

System check identified no issues (0 silenced).
May 17, 2017 - 21:49:16
Django version 1.10.6, using settings 'restfulapi.settings'
Starting development server at http://0.0.0.0:8000/
Quit the server with CONTROL-C.
Internal Server Error: /api/
Traceback (most recent call last):
  File "/root/python27/lib/python2.7/site-packages/django/core/handlers/exception.py", line 42, in inner
    response = get_response(request)
  File "/root/python27/lib/python2.7/site-packages/django/core/handlers/base.py", line 187, in _get_response
    response = self.process_exception_by_middleware(e, request)
  File "/root/python27/lib/python2.7/site-packages/django/core/handlers/base.py", line 185, in _get_response
    response = wrapped_callback(request, *callback_args, **callback_kwargs)
  File "/root/scripts/restfulapi/api/views.py", line 11, in api_list
    'auth': unicode(request.auth),  # None
AttributeError: 'WSGIRequest' object has no attribute 'auth'
[17/May/2017 21:50:10] "GET /api/?format=api HTTP/1.1" 500 64400
Performing system checks...

System check identified no issues (0 silenced).
May 17, 2017 - 21:50:06
Django version 1.10.6, using settings 'restfulapi.settings'
Starting development server at http://0.0.0.0:8000/
Quit the server with CONTROL-C.
[17/May/2017 21:50:37] "GET /api/ HTTP/1.1" 403 4542
[17/May/2017 21:50:40] "GET /api/?format=api HTTP/1.1" 403 4575
[17/May/2017 21:50:41] "GET /api/?format=api HTTP/1.1" 403 4575
[17/May/2017 21:50:42] "GET /api/?format=json HTTP/1.1" 403 58
[17/May/2017 21:50:54] "GET /api/?format=json HTTP/1.1" 403 58
Performing system checks...

System check identified no issues (0 silenced).
May 17, 2017 - 21:50:30
Django version 1.10.6, using settings 'restfulapi.settings'
Starting development server at http://0.0.0.0:8000/
Quit the server with CONTROL-C.
[17/May/2017 21:52:55] "GET /api HTTP/1.1" 301 0
[17/May/2017 21:52:58] "GET /api/ HTTP/1.1" 403 58
[17/May/2017 21:54:09] "GET /api/ HTTP/1.1" 200 34
[17/May/2017 21:54:26] "GET /api/ HTTP/1.1" 403 58
[17/May/2017 21:54:29] "GET /api/ HTTP/1.1" 200 34
Performing system checks...

System check identified no issues (0 silenced).
May 17, 2017 - 21:51:56
Django version 1.10.6, using settings 'restfulapi.settings'
Starting development server at http://0.0.0.0:8000/
Quit the server with CONTROL-C.
[17/May/2017 21:55:11] "GET /api/ HTTP/1.1" 200 20
Performing system checks...

System check identified no issues (0 silenced).
May 17, 2017 - 21:55:08
Django version 1.10.6, using settings 'restfulapi.settings'
Starting development server at http://0.0.0.0:8000/
Quit the server with CONTROL-C.
[17/May/2017 21:59:12] "GET /api/ HTTP/1.1" 200 20
[17/May/2017 21:59:14] "GET /api/ HTTP/1.1" 200 20
[17/May/2017 21:59:15] "GET /api/ HTTP/1.1" 200 20
[17/May/2017 21:59:16] "GET /api/ HTTP/1.1" 200 20
[17/May/2017 21:59:19] "GET /api/ HTTP/1.1" 200 24
[17/May/2017 21:59:28] "GET /api/ HTTP/1.1" 200 24
[17/May/2017 21:59:35] "GET /api/ HTTP/1.1" 200 24
[17/May/2017 21:59:47] "GET /api/ HTTP/1.1" 200 24
[17/May/2017 21:59:49] "GET /api/ HTTP/1.1" 200 24
[17/May/2017 22:01:20] "GET /api/ HTTP/1.1" 200 24
Performing system checks...

System check identified no issues (0 silenced).
May 17, 2017 - 21:58:51
Django version 1.10.6, using settings 'restfulapi.settings'
Starting development server at http://0.0.0.0:8000/
Quit the server with CONTROL-C.
[17/May/2017 22:02:12] "GET /api/ HTTP/1.1" 403 58
[17/May/2017 22:02:16] "GET /api/ HTTP/1.1" 200 20
Not Found: /
[17/May/2017 22:37:44] "GET / HTTP/1.1" 404 1960
[17/May/2017 22:37:53] "GET /api/ HTTP/1.1" 403 4542
[17/May/2017 22:38:03] "GET /api/?json HTTP/1.1" 403 4572
Not Found: /api/format
[17/May/2017 22:38:11] "GET /api/format?json HTTP/1.1" 404 1995
Not Found: /api/format=
[17/May/2017 22:38:15] "GET /api/format=?json HTTP/1.1" 404 2000
[17/May/2017 22:38:22] "GET /api/?format=json HTTP/1.1" 403 58
[17/May/2017 22:38:44] "GET /api/ HTTP/1.1" 200 20
[17/May/2017 22:38:58] "GET /api/ HTTP/1.1" 200 20
[17/May/2017 22:39:24] "GET /api/?format=json HTTP/1.1" 403 58
